------------------
Policy(
  (main_net): FCNet(
    (layers): ModuleList(
      (0): Linear(in_features=4, out_features=64, bias=True)
      (1): Linear(in_features=64, out_features=64, bias=True)
    )
  )
  (fc_actor): Linear(in_features=64, out_features=2, bias=True)
  (fc_critic): Linear(in_features=64, out_features=1, bias=True)
)
------------------
Episode 0	Average Score: 191.50
[192. 189. 191. 193. 191. 192. 191. 193.]
/Users/liwenyu/Documents/GitHub/RTDM/utils.py:51: UserWarning: Creating a tensor from a list of numpy.ndarrays is extremely slow. Please consider converting the list to a single numpy.ndarray with numpy.array() before converting to a tensor. (Triggered internally at  ../torch/csrc/utils/tensor_new.cpp:201.)
  actions = torch.tensor(actions, dtype=torch.long, device=device).view(-1,)
Episode 100	Average Score: 192.08
[196. 197. 196. 197. 196. 195. 195. 197.]
Episode 200	Average Score: 198.09
[199. 199. 199. 199. 199. 198. 199. 199.]
Episode 300	Average Score: 199.05
[199. 200. 200. 199. 199. 199. 199. 199.]
Episode 400	Average Score: 199.65
[200. 200. 200. 200. 200. 200. 200. 200.]
Process Process-9:
Process Process-8:
Process Process-7:
Process Process-5:
Process Process-4:
Process Process-6:
Process Process-3:
Process Process-2:
Traceback (most recent call last):
Traceback (most recent call last):
Traceback (most recent call last):
Traceback (most recent call last):
  File "/Library/Frameworks/Python.framework/Versions/3.9/lib/python3.9/multiprocessing/process.py", line 315, in _bootstrap
    self.run()
  File "/Library/Frameworks/Python.framework/Versions/3.9/lib/python3.9/multiprocessing/process.py", line 315, in _bootstrap
    self.run()
  File "/Library/Frameworks/Python.framework/Versions/3.9/lib/python3.9/multiprocessing/process.py", line 108, in run
    self._target(*self._args, **self._kwargs)
  File "/Library/Frameworks/Python.framework/Versions/3.9/lib/python3.9/multiprocessing/process.py", line 315, in _bootstrap
    self.run()
  File "/Users/liwenyu/Documents/GitHub/RTDM/parallelEnv.py", line 98, in worker
    cmd, data = remote.recv()
  File "/Library/Frameworks/Python.framework/Versions/3.9/lib/python3.9/multiprocessing/process.py", line 108, in run
    self._target(*self._args, **self._kwargs)
  File "/Library/Frameworks/Python.framework/Versions/3.9/lib/python3.9/multiprocessing/connection.py", line 255, in recv
    buf = self._recv_bytes()
  File "/Library/Frameworks/Python.framework/Versions/3.9/lib/python3.9/multiprocessing/connection.py", line 419, in _recv_bytes
    buf = self._recv(4)
  File "/Library/Frameworks/Python.framework/Versions/3.9/lib/python3.9/multiprocessing/process.py", line 315, in _bootstrap
    self.run()
  File "/Library/Frameworks/Python.framework/Versions/3.9/lib/python3.9/multiprocessing/connection.py", line 388, in _recv
    raise EOFError
  File "/Library/Frameworks/Python.framework/Versions/3.9/lib/python3.9/multiprocessing/process.py", line 108, in run
    self._target(*self._args, **self._kwargs)
  File "/Library/Frameworks/Python.framework/Versions/3.9/lib/python3.9/multiprocessing/process.py", line 108, in run
    self._target(*self._args, **self._kwargs)
  File "/Users/liwenyu/Documents/GitHub/RTDM/parallelEnv.py", line 98, in worker
    cmd, data = remote.recv()
  File "/Library/Frameworks/Python.framework/Versions/3.9/lib/python3.9/multiprocessing/connection.py", line 255, in recv
    buf = self._recv_bytes()
Traceback (most recent call last):
Traceback (most recent call last):
  File "/Users/liwenyu/Documents/GitHub/RTDM/parallelEnv.py", line 98, in worker
    cmd, data = remote.recv()
  File "/Library/Frameworks/Python.framework/Versions/3.9/lib/python3.9/multiprocessing/connection.py", line 419, in _recv_bytes
    buf = self._recv(4)
  File "/Library/Frameworks/Python.framework/Versions/3.9/lib/python3.9/multiprocessing/connection.py", line 388, in _recv
    raise EOFError
  File "/Library/Frameworks/Python.framework/Versions/3.9/lib/python3.9/multiprocessing/connection.py", line 255, in recv
    buf = self._recv_bytes()
  File "/Library/Frameworks/Python.framework/Versions/3.9/lib/python3.9/multiprocessing/connection.py", line 419, in _recv_bytes
    buf = self._recv(4)
EOFError
  File "/Library/Frameworks/Python.framework/Versions/3.9/lib/python3.9/multiprocessing/connection.py", line 388, in _recv
    raise EOFError
EOFError
  File "/Library/Frameworks/Python.framework/Versions/3.9/lib/python3.9/multiprocessing/process.py", line 315, in _bootstrap
    self.run()
  File "/Library/Frameworks/Python.framework/Versions/3.9/lib/python3.9/multiprocessing/process.py", line 315, in _bootstrap
    self.run()
  File "/Library/Frameworks/Python.framework/Versions/3.9/lib/python3.9/multiprocessing/process.py", line 108, in run
    self._target(*self._args, **self._kwargs)
  File "/Users/liwenyu/Documents/GitHub/RTDM/parallelEnv.py", line 98, in worker
    cmd, data = remote.recv()
  File "/Users/liwenyu/Documents/GitHub/RTDM/parallelEnv.py", line 98, in worker
    cmd, data = remote.recv()
  File "/Library/Frameworks/Python.framework/Versions/3.9/lib/python3.9/multiprocessing/connection.py", line 255, in recv
    buf = self._recv_bytes()
  File "/Library/Frameworks/Python.framework/Versions/3.9/lib/python3.9/multiprocessing/connection.py", line 419, in _recv_bytes
    buf = self._recv(4)
  File "/Library/Frameworks/Python.framework/Versions/3.9/lib/python3.9/multiprocessing/connection.py", line 388, in _recv
    raise EOFError
  File "/Library/Frameworks/Python.framework/Versions/3.9/lib/python3.9/multiprocessing/connection.py", line 255, in recv
    buf = self._recv_bytes()
  File "/Library/Frameworks/Python.framework/Versions/3.9/lib/python3.9/multiprocessing/connection.py", line 419, in _recv_bytes
    buf = self._recv(4)
  File "/Library/Frameworks/Python.framework/Versions/3.9/lib/python3.9/multiprocessing/connection.py", line 388, in _recv
    raise EOFError
EOFError
EOFError
EOFError
Traceback (most recent call last):
  File "/Library/Frameworks/Python.framework/Versions/3.9/lib/python3.9/multiprocessing/process.py", line 315, in _bootstrap
    self.run()
  File "/Library/Frameworks/Python.framework/Versions/3.9/lib/python3.9/multiprocessing/process.py", line 108, in run
    self._target(*self._args, **self._kwargs)
  File "/Users/liwenyu/Documents/GitHub/RTDM/parallelEnv.py", line 98, in worker
    cmd, data = remote.recv()
  File "/Library/Frameworks/Python.framework/Versions/3.9/lib/python3.9/multiprocessing/connection.py", line 255, in recv
    buf = self._recv_bytes()
  File "/Library/Frameworks/Python.framework/Versions/3.9/lib/python3.9/multiprocessing/connection.py", line 419, in _recv_bytes
    buf = self._recv(4)
  File "/Library/Frameworks/Python.framework/Versions/3.9/lib/python3.9/multiprocessing/process.py", line 108, in run
    self._target(*self._args, **self._kwargs)
  File "/Library/Frameworks/Python.framework/Versions/3.9/lib/python3.9/multiprocessing/connection.py", line 388, in _recv
    raise EOFError
  File "/Users/liwenyu/Documents/GitHub/RTDM/parallelEnv.py", line 98, in worker
    cmd, data = remote.recv()
EOFError
  File "/Library/Frameworks/Python.framework/Versions/3.9/lib/python3.9/multiprocessing/connection.py", line 255, in recv
    buf = self._recv_bytes()
  File "/Library/Frameworks/Python.framework/Versions/3.9/lib/python3.9/multiprocessing/connection.py", line 419, in _recv_bytes
    buf = self._recv(4)
  File "/Library/Frameworks/Python.framework/Versions/3.9/lib/python3.9/multiprocessing/connection.py", line 388, in _recv
    raise EOFError
EOFError
Traceback (most recent call last):
  File "/Library/Frameworks/Python.framework/Versions/3.9/lib/python3.9/multiprocessing/process.py", line 315, in _bootstrap
    self.run()
  File "/Library/Frameworks/Python.framework/Versions/3.9/lib/python3.9/multiprocessing/process.py", line 108, in run
    self._target(*self._args, **self._kwargs)
  File "/Users/liwenyu/Documents/GitHub/RTDM/parallelEnv.py", line 98, in worker
    cmd, data = remote.recv()
  File "/Library/Frameworks/Python.framework/Versions/3.9/lib/python3.9/multiprocessing/connection.py", line 255, in recv
    buf = self._recv_bytes()
  File "/Library/Frameworks/Python.framework/Versions/3.9/lib/python3.9/multiprocessing/connection.py", line 419, in _recv_bytes
    buf = self._recv(4)
  File "/Library/Frameworks/Python.framework/Versions/3.9/lib/python3.9/multiprocessing/connection.py", line 388, in _recv
    raise EOFError
EOFError
0
2022-02-03 16:31:51.834 Python[1774:68235] ApplePersistenceIgnoreState: Existing state will not be touched. New state will be written to /var/folders/yt/3gz8yy8s1ks3w9hgqhvppyyc0000gn/T/org.python.python.savedState
reward : 200
[200]
reward : 1
[200, 1]
reward : 1
[200, 1, 1]
reward : 1
[200, 1, 1, 1]
reward : 1
[200, 1, 1, 1, 1]
reward : 1
[200, 1, 1, 1, 1, 1]
reward : 1
[200, 1, 1, 1, 1, 1, 1]
reward : 1
[200, 1, 1, 1, 1, 1, 1, 1]
reward : 1
[200, 1, 1, 1, 1, 1, 1, 1, 1]
reward : 1
[200, 1, 1, 1, 1, 1, 1, 1, 1, 1]
[20.9]
0
reward : 200
[200]
reward : 200
[200, 200]
reward : 200
[200, 200, 200]
reward : 200
[200, 200, 200, 200]
reward : 200
[200, 200, 200, 200, 200]
reward : 200
[200, 200, 200, 200, 200, 200]
reward : 200
[200, 200, 200, 200, 200, 200, 200]
2
/Library/Frameworks/Python.framework/Versions/3.9/lib/python3.9/site-packages/gym/envs/classic_control/cartpole.py:150: UserWarning: [33mWARN: You are calling 'step()' even though this environment has already returned done = True. You should always call 'reset()' once you receive 'done = True' -- any further steps are undefined behavior.
  logger.warn(
[288.9566160520607]
2
/Library/Frameworks/Python.framework/Versions/3.9/lib/python3.9/site-packages/matplotlib/animation.py:973: UserWarning: Animation was deleted without rendering anything. This is most likely unintended. To prevent deletion, assign the Animation to a variable that exists for as long as you need the Animation.
  warnings.warn(
Exception in thread Thread-11:
Traceback (most recent call last):
  File "/Library/Frameworks/Python.framework/Versions/3.9/lib/python3.9/threading.py", line 973, in _bootstrap_inner
    self.run()
  File "/Library/Frameworks/Python.framework/Versions/3.9/lib/python3.9/threading.py", line 910, in run
    self._target(*self._args, **self._kwargs)
  File "/Library/Frameworks/Python.framework/Versions/3.9/lib/python3.9/site-packages/wandb/sdk/wandb_run.py", line 149, in check_network_status
    status_response = self._interface.communicate_network_status()
  File "/Library/Frameworks/Python.framework/Versions/3.9/lib/python3.9/site-packages/wandb/sdk/interface/interface.py", line 120, in communicate_network_status
    resp = self._communicate_network_status(status)
  File "/Library/Frameworks/Python.framework/Versions/3.9/lib/python3.9/site-packages/wandb/sdk/interface/interface_queue.py", line 411, in _communicate_network_status
    resp = self._communicate(req, local=True)
  File "/Library/Frameworks/Python.framework/Versions/3.9/lib/python3.9/site-packages/wandb/sdk/interface/interface_queue.py", line 232, in _communicate
    return self._communicate_async(rec, local=local).get(timeout=timeout)
  File "/Library/Frameworks/Python.framework/Versions/3.9/lib/python3.9/site-packages/wandb/sdk/interface/interface_queue.py", line 237, in _communicate_async
    raise Exception("The wandb backend process has shutdown")
Exception: The wandb backend process has shutdown
Exception in thread Thread-10:
Traceback (most recent call last):
  File "/Library/Frameworks/Python.framework/Versions/3.9/lib/python3.9/threading.py", line 973, in _bootstrap_inner
    self.run()
  File "/Library/Frameworks/Python.framework/Versions/3.9/lib/python3.9/threading.py", line 910, in run
    self._target(*self._args, **self._kwargs)
  File "/Library/Frameworks/Python.framework/Versions/3.9/lib/python3.9/site-packages/wandb/sdk/wandb_run.py", line 167, in check_status
    status_response = self._interface.communicate_stop_status()
  File "/Library/Frameworks/Python.framework/Versions/3.9/lib/python3.9/site-packages/wandb/sdk/interface/interface.py", line 109, in communicate_stop_status
    resp = self._communicate_stop_status(status)
  File "/Library/Frameworks/Python.framework/Versions/3.9/lib/python3.9/site-packages/wandb/sdk/interface/interface_queue.py", line 401, in _communicate_stop_status
    resp = self._communicate(req, local=True)
  File "/Library/Frameworks/Python.framework/Versions/3.9/lib/python3.9/site-packages/wandb/sdk/interface/interface_queue.py", line 232, in _communicate
    return self._communicate_async(rec, local=local).get(timeout=timeout)
  File "/Library/Frameworks/Python.framework/Versions/3.9/lib/python3.9/site-packages/wandb/sdk/interface/interface_queue.py", line 237, in _communicate_async
    raise Exception("The wandb backend process has shutdown")
Exception: The wandb backend process has shutdown
Error in callback <function _WandbInit._resume_backend at 0x7fb5277343a0> (for pre_run_cell):
Error in callback <function _WandbInit._pause_backend at 0x7fb528da1a60> (for post_run_cell):
Error in callback <function _WandbInit._resume_backend at 0x7fb5277343a0> (for pre_run_cell):
Error in callback <function _WandbInit._pause_backend at 0x7fb528da1a60> (for post_run_cell):
Error in callback <function _WandbInit._resume_backend at 0x7fb5277343a0> (for pre_run_cell):
Error in callback <function _WandbInit._pause_backend at 0x7fb528da1a60> (for post_run_cell):
Error in callback <function _WandbInit._resume_backend at 0x7fb5277343a0> (for pre_run_cell):