------------------
Policy(
  (main_net): FCNet(
    (layers): ModuleList(
      (0): Linear(in_features=4, out_features=64, bias=True)
      (1): Linear(in_features=64, out_features=64, bias=True)
    )
  )
  (fc_actor): Linear(in_features=64, out_features=2, bias=True)
  (fc_critic): Linear(in_features=64, out_features=1, bias=True)
)
------------------
Episode 0	Average Score: 191.50
[192. 189. 191. 193. 191. 192. 191. 193.]
/Users/liwenyu/Documents/GitHub/RTDM/utils.py:51: UserWarning: Creating a tensor from a list of numpy.ndarrays is extremely slow. Please consider converting the list to a single numpy.ndarray with numpy.array() before converting to a tensor. (Triggered internally at  ../torch/csrc/utils/tensor_new.cpp:201.)
  actions = torch.tensor(actions, dtype=torch.long, device=device).view(-1,)
Episode 100	Average Score: 192.30
[196. 196. 193. 197. 196. 195. 197. 196.]
Episode 200	Average Score: 198.20
[199. 198. 199. 198. 199. 199. 199. 199.]
Episode 300	Average Score: 199.09
[199. 199. 200. 199. 199. 199. 199. 199.]
Process Process-9:
Process Process-6:
Process Process-5:
Process Process-7:
Process Process-3:
Process Process-4:
Process Process-8:
Process Process-2:
Traceback (most recent call last):
Traceback (most recent call last):
Traceback (most recent call last):
Traceback (most recent call last):
  File "/Library/Frameworks/Python.framework/Versions/3.9/lib/python3.9/multiprocessing/process.py", line 315, in _bootstrap
    self.run()
  File "/Library/Frameworks/Python.framework/Versions/3.9/lib/python3.9/multiprocessing/process.py", line 315, in _bootstrap
    self.run()
  File "/Library/Frameworks/Python.framework/Versions/3.9/lib/python3.9/multiprocessing/process.py", line 315, in _bootstrap
    self.run()
  File "/Library/Frameworks/Python.framework/Versions/3.9/lib/python3.9/multiprocessing/process.py", line 315, in _bootstrap
    self.run()
  File "/Library/Frameworks/Python.framework/Versions/3.9/lib/python3.9/multiprocessing/process.py", line 108, in run
    self._target(*self._args, **self._kwargs)
Traceback (most recent call last):
Traceback (most recent call last):
  File "/Users/liwenyu/Documents/GitHub/RTDM/parallelEnv.py", line 98, in worker
    cmd, data = remote.recv()
  File "/Library/Frameworks/Python.framework/Versions/3.9/lib/python3.9/multiprocessing/connection.py", line 255, in recv
    buf = self._recv_bytes()
  File "/Library/Frameworks/Python.framework/Versions/3.9/lib/python3.9/multiprocessing/process.py", line 108, in run
    self._target(*self._args, **self._kwargs)
  File "/Library/Frameworks/Python.framework/Versions/3.9/lib/python3.9/multiprocessing/connection.py", line 419, in _recv_bytes
    buf = self._recv(4)
  File "/Library/Frameworks/Python.framework/Versions/3.9/lib/python3.9/multiprocessing/connection.py", line 388, in _recv
    raise EOFError
  File "/Users/liwenyu/Documents/GitHub/RTDM/parallelEnv.py", line 98, in worker
    cmd, data = remote.recv()
  File "/Library/Frameworks/Python.framework/Versions/3.9/lib/python3.9/multiprocessing/connection.py", line 255, in recv
    buf = self._recv_bytes()
  File "/Library/Frameworks/Python.framework/Versions/3.9/lib/python3.9/multiprocessing/connection.py", line 419, in _recv_bytes
    buf = self._recv(4)
EOFError
  File "/Library/Frameworks/Python.framework/Versions/3.9/lib/python3.9/multiprocessing/connection.py", line 388, in _recv
    raise EOFError
EOFError
  File "/Library/Frameworks/Python.framework/Versions/3.9/lib/python3.9/multiprocessing/process.py", line 315, in _bootstrap
    self.run()
Traceback (most recent call last):
  File "/Library/Frameworks/Python.framework/Versions/3.9/lib/python3.9/multiprocessing/process.py", line 108, in run
    self._target(*self._args, **self._kwargs)
  File "/Users/liwenyu/Documents/GitHub/RTDM/parallelEnv.py", line 98, in worker
    cmd, data = remote.recv()
  File "/Library/Frameworks/Python.framework/Versions/3.9/lib/python3.9/multiprocessing/connection.py", line 255, in recv
    buf = self._recv_bytes()
  File "/Library/Frameworks/Python.framework/Versions/3.9/lib/python3.9/multiprocessing/connection.py", line 419, in _recv_bytes
    buf = self._recv(4)
  File "/Library/Frameworks/Python.framework/Versions/3.9/lib/python3.9/multiprocessing/process.py", line 108, in run
    self._target(*self._args, **self._kwargs)
  File "/Library/Frameworks/Python.framework/Versions/3.9/lib/python3.9/multiprocessing/connection.py", line 388, in _recv
    raise EOFError
  File "/Users/liwenyu/Documents/GitHub/RTDM/parallelEnv.py", line 98, in worker
    cmd, data = remote.recv()
  File "/Library/Frameworks/Python.framework/Versions/3.9/lib/python3.9/multiprocessing/process.py", line 108, in run
    self._target(*self._args, **self._kwargs)
  File "/Library/Frameworks/Python.framework/Versions/3.9/lib/python3.9/multiprocessing/connection.py", line 255, in recv
    buf = self._recv_bytes()
  File "/Library/Frameworks/Python.framework/Versions/3.9/lib/python3.9/multiprocessing/process.py", line 315, in _bootstrap
    self.run()
  File "/Library/Frameworks/Python.framework/Versions/3.9/lib/python3.9/multiprocessing/connection.py", line 419, in _recv_bytes
    buf = self._recv(4)
  File "/Library/Frameworks/Python.framework/Versions/3.9/lib/python3.9/multiprocessing/process.py", line 108, in run
    self._target(*self._args, **self._kwargs)
  File "/Users/liwenyu/Documents/GitHub/RTDM/parallelEnv.py", line 98, in worker
    cmd, data = remote.recv()
  File "/Users/liwenyu/Documents/GitHub/RTDM/parallelEnv.py", line 98, in worker
    cmd, data = remote.recv()
  File "/Library/Frameworks/Python.framework/Versions/3.9/lib/python3.9/multiprocessing/process.py", line 315, in _bootstrap
    self.run()
  File "/Library/Frameworks/Python.framework/Versions/3.9/lib/python3.9/multiprocessing/connection.py", line 255, in recv
    buf = self._recv_bytes()
  File "/Library/Frameworks/Python.framework/Versions/3.9/lib/python3.9/multiprocessing/connection.py", line 255, in recv
    buf = self._recv_bytes()
  File "/Library/Frameworks/Python.framework/Versions/3.9/lib/python3.9/multiprocessing/process.py", line 108, in run
    self._target(*self._args, **self._kwargs)
  File "/Library/Frameworks/Python.framework/Versions/3.9/lib/python3.9/multiprocessing/connection.py", line 419, in _recv_bytes
    buf = self._recv(4)
  File "/Users/liwenyu/Documents/GitHub/RTDM/parallelEnv.py", line 98, in worker
    cmd, data = remote.recv()
  File "/Library/Frameworks/Python.framework/Versions/3.9/lib/python3.9/multiprocessing/connection.py", line 388, in _recv
    raise EOFError
  File "/Library/Frameworks/Python.framework/Versions/3.9/lib/python3.9/multiprocessing/connection.py", line 255, in recv
    buf = self._recv_bytes()
  File "/Library/Frameworks/Python.framework/Versions/3.9/lib/python3.9/multiprocessing/connection.py", line 388, in _recv
    raise EOFError
  File "/Library/Frameworks/Python.framework/Versions/3.9/lib/python3.9/multiprocessing/connection.py", line 419, in _recv_bytes
    buf = self._recv(4)
  File "/Library/Frameworks/Python.framework/Versions/3.9/lib/python3.9/multiprocessing/connection.py", line 419, in _recv_bytes
    buf = self._recv(4)
EOFError
Traceback (most recent call last):
EOFError
  File "/Library/Frameworks/Python.framework/Versions/3.9/lib/python3.9/multiprocessing/connection.py", line 388, in _recv
    raise EOFError
  File "/Library/Frameworks/Python.framework/Versions/3.9/lib/python3.9/multiprocessing/connection.py", line 388, in _recv
    raise EOFError
EOFError
EOFError
  File "/Library/Frameworks/Python.framework/Versions/3.9/lib/python3.9/multiprocessing/process.py", line 315, in _bootstrap
    self.run()
  File "/Library/Frameworks/Python.framework/Versions/3.9/lib/python3.9/multiprocessing/process.py", line 108, in run
    self._target(*self._args, **self._kwargs)
  File "/Users/liwenyu/Documents/GitHub/RTDM/parallelEnv.py", line 98, in worker
    cmd, data = remote.recv()
  File "/Library/Frameworks/Python.framework/Versions/3.9/lib/python3.9/multiprocessing/connection.py", line 255, in recv
    buf = self._recv_bytes()
  File "/Library/Frameworks/Python.framework/Versions/3.9/lib/python3.9/multiprocessing/connection.py", line 419, in _recv_bytes
    buf = self._recv(4)
  File "/Library/Frameworks/Python.framework/Versions/3.9/lib/python3.9/multiprocessing/connection.py", line 388, in _recv
    raise EOFError
EOFError
EOFError
2022-01-23 23:11:42.752 Python[1053:11723] ApplePersistenceIgnoreState: Existing state will not be touched. New state will be written to /var/folders/yt/3gz8yy8s1ks3w9hgqhvppyyc0000gn/T/org.python.python.savedState
Episode 400	Average Score: 199.61
[199. 200. 199. 200. 200. 200. 200. 200.]
reward : 10
0
9
reward : 10
wandb: ERROR Dropped streaming file chunk (see wandb/debug-internal.log)
ERROR:root:dropped chunk 404 Client Error: Not Found for url: https://api.wandb.ai/files/lwyjo/ppo/150wspd1/file_stream
NoneType: None
wandb: ERROR Dropped streaming file chunk (see wandb/debug-internal.log)
ERROR:root:dropped chunk 404 Client Error: Not Found for url: https://api.wandb.ai/files/lwyjo/ppo/150wspd1/file_stream
NoneType: None
wandb: ERROR Dropped streaming file chunk (see wandb/debug-internal.log)
ERROR:root:dropped chunk 404 Client Error: Not Found for url: https://api.wandb.ai/files/lwyjo/ppo/150wspd1/file_stream
NoneType: None
wandb: ERROR Dropped streaming file chunk (see wandb/debug-internal.log)
ERROR:root:dropped chunk 404 Client Error: Not Found for url: https://api.wandb.ai/files/lwyjo/ppo/150wspd1/file_stream
NoneType: None
wandb: ERROR Dropped streaming file chunk (see wandb/debug-internal.log)
ERROR:root:dropped chunk 404 Client Error: Not Found for url: https://api.wandb.ai/files/lwyjo/ppo/150wspd1/file_stream
