2022-02-03 15:44:52,431 INFO    MainThread:1212 [internal.py:wandb_internal():87] W&B internal server running at pid: 1212, started at: 2022-02-03 15:44:52.430870
2022-02-03 15:44:52,433 DEBUG   HandlerThread:1212 [handler.py:handle_request():130] handle_request: check_version
2022-02-03 15:44:52,433 INFO    WriterThread:1212 [datastore.py:open_for_write():77] open: /Users/liwenyu/Documents/GitHub/RTDM/wandb/run-20220203_154451-3i31rgxo/run-3i31rgxo.wandb
2022-02-03 15:44:52,435 DEBUG   SenderThread:1212 [sender.py:send():238] send: header
2022-02-03 15:44:52,436 DEBUG   SenderThread:1212 [sender.py:send_request():252] send_request: check_version
2022-02-03 15:44:57,442 DEBUG   SenderThread:1212 [sender.py:send():238] send: run
2022-02-03 15:45:26,610 DEBUG   HandlerThread:1212 [handler.py:handle_request():130] handle_request: shutdown
2022-02-03 15:45:26,611 INFO    HandlerThread:1212 [handler.py:finish():731] shutting down handler
2022-02-03 15:45:26,723 INFO    WriterThread:1212 [datastore.py:close():281] close: /Users/liwenyu/Documents/GitHub/RTDM/wandb/run-20220203_154451-3i31rgxo/run-3i31rgxo.wandb
2022-02-03 15:45:30,874 ERROR   SenderThread:1212 [retry.py:__call__():126] Retry attempt failed:
Traceback (most recent call last):
  File "/Library/Frameworks/Python.framework/Versions/3.9/lib/python3.9/site-packages/urllib3/connection.py", line 169, in _new_conn
    conn = connection.create_connection(
  File "/Library/Frameworks/Python.framework/Versions/3.9/lib/python3.9/site-packages/urllib3/util/connection.py", line 96, in create_connection
    raise err
  File "/Library/Frameworks/Python.framework/Versions/3.9/lib/python3.9/site-packages/urllib3/util/connection.py", line 86, in create_connection
    sock.connect(sa)
socket.timeout: timed out

During handling of the above exception, another exception occurred:

Traceback (most recent call last):
  File "/Library/Frameworks/Python.framework/Versions/3.9/lib/python3.9/site-packages/urllib3/connectionpool.py", line 699, in urlopen
    httplib_response = self._make_request(
  File "/Library/Frameworks/Python.framework/Versions/3.9/lib/python3.9/site-packages/urllib3/connectionpool.py", line 382, in _make_request
    self._validate_conn(conn)
  File "/Library/Frameworks/Python.framework/Versions/3.9/lib/python3.9/site-packages/urllib3/connectionpool.py", line 1010, in _validate_conn
    conn.connect()
  File "/Library/Frameworks/Python.framework/Versions/3.9/lib/python3.9/site-packages/urllib3/connection.py", line 353, in connect
    conn = self._new_conn()
  File "/Library/Frameworks/Python.framework/Versions/3.9/lib/python3.9/site-packages/urllib3/connection.py", line 174, in _new_conn
    raise ConnectTimeoutError(
urllib3.exceptions.ConnectTimeoutError: (<urllib3.connection.HTTPSConnection object at 0x7fae7d4f0100>, 'Connection to api.wandb.ai timed out. (connect timeout=10)')

During handling of the above exception, another exception occurred:

Traceback (most recent call last):
  File "/Library/Frameworks/Python.framework/Versions/3.9/lib/python3.9/site-packages/requests/adapters.py", line 439, in send
    resp = conn.urlopen(
  File "/Library/Frameworks/Python.framework/Versions/3.9/lib/python3.9/site-packages/urllib3/connectionpool.py", line 755, in urlopen
    retries = retries.increment(
  File "/Library/Frameworks/Python.framework/Versions/3.9/lib/python3.9/site-packages/urllib3/util/retry.py", line 574, in increment
    raise MaxRetryError(_pool, url, error or ResponseError(cause))
urllib3.exceptions.MaxRetryError: HTTPSConnectionPool(host='api.wandb.ai', port=443): Max retries exceeded with url: /graphql (Caused by ConnectTimeoutError(<urllib3.connection.HTTPSConnection object at 0x7fae7d4f0100>, 'Connection to api.wandb.ai timed out. (connect timeout=10)'))

During handling of the above exception, another exception occurred:

Traceback (most recent call last):
  File "/Library/Frameworks/Python.framework/Versions/3.9/lib/python3.9/site-packages/wandb/sdk/lib/retry.py", line 102, in __call__
    result = self._call_fn(*args, **kwargs)
  File "/Library/Frameworks/Python.framework/Versions/3.9/lib/python3.9/site-packages/wandb/sdk/internal/internal_api.py", line 141, in execute
    return self.client.execute(*args, **kwargs)
  File "/Library/Frameworks/Python.framework/Versions/3.9/lib/python3.9/site-packages/wandb/vendor/gql-0.2.0/gql/client.py", line 52, in execute
    result = self._get_result(document, *args, **kwargs)
  File "/Library/Frameworks/Python.framework/Versions/3.9/lib/python3.9/site-packages/wandb/vendor/gql-0.2.0/gql/client.py", line 60, in _get_result
    return self.transport.execute(document, *args, **kwargs)
  File "/Library/Frameworks/Python.framework/Versions/3.9/lib/python3.9/site-packages/wandb/vendor/gql-0.2.0/gql/transport/requests.py", line 38, in execute
    request = requests.post(self.url, **post_args)
  File "/Library/Frameworks/Python.framework/Versions/3.9/lib/python3.9/site-packages/requests/api.py", line 117, in post
    return request('post', url, data=data, json=json, **kwargs)
  File "/Library/Frameworks/Python.framework/Versions/3.9/lib/python3.9/site-packages/requests/api.py", line 61, in request
    return session.request(method=method, url=url, **kwargs)
  File "/Library/Frameworks/Python.framework/Versions/3.9/lib/python3.9/site-packages/requests/sessions.py", line 542, in request
    resp = self.send(prep, **send_kwargs)
  File "/Library/Frameworks/Python.framework/Versions/3.9/lib/python3.9/site-packages/requests/sessions.py", line 655, in send
    r = adapter.send(request, **kwargs)
  File "/Library/Frameworks/Python.framework/Versions/3.9/lib/python3.9/site-packages/requests/adapters.py", line 504, in send
    raise ConnectTimeout(e, request=request)
requests.exceptions.ConnectTimeout: HTTPSConnectionPool(host='api.wandb.ai', port=443): Max retries exceeded with url: /graphql (Caused by ConnectTimeoutError(<urllib3.connection.HTTPSConnection object at 0x7fae7d4f0100>, 'Connection to api.wandb.ai timed out. (connect timeout=10)'))
2022-02-03 15:48:34,298 INFO    SenderThread:1212 [dir_watcher.py:__init__():169] watching files in: /Users/liwenyu/Documents/GitHub/RTDM/wandb/run-20220203_154451-3i31rgxo/files
2022-02-03 15:48:34,298 INFO    SenderThread:1212 [sender.py:_start_run_threads():825] run started: 3i31rgxo with start time 1643903091
2022-02-03 15:48:34,298 INFO    SenderThread:1212 [sender.py:finish():1091] shutting down sender
2022-02-03 15:48:34,298 INFO    SenderThread:1212 [dir_watcher.py:finish():283] shutting down directory watcher
2022-02-03 15:48:35,302 INFO    SenderThread:1212 [dir_watcher.py:finish():313] scan: /Users/liwenyu/Documents/GitHub/RTDM/wandb/run-20220203_154451-3i31rgxo/files
2022-02-03 15:48:35,302 INFO    SenderThread:1212 [dir_watcher.py:finish():327] scan save: /Users/liwenyu/Documents/GitHub/RTDM/wandb/run-20220203_154451-3i31rgxo/files/config.yaml config.yaml
2022-02-03 15:48:35,302 INFO    SenderThread:1212 [file_pusher.py:finish():177] shutting down file pusher
2022-02-03 15:48:35,302 INFO    SenderThread:1212 [file_pusher.py:join():182] waiting for file pusher
2022-02-03 15:48:35,845 INFO    Thread-10 :1212 [upload_job.py:push():137] Uploaded file /Users/liwenyu/Documents/GitHub/RTDM/wandb/run-20220203_154451-3i31rgxo/files/config.yaml
2022-02-03 15:48:36,480 INFO    MainThread:1212 [internal.py:handle_exit():77] Internal process exited
