2022-02-03 15:44:51,448 INFO    MainThread:1199 [wandb_setup.py:_flush():71] setting env: {}
2022-02-03 15:44:51,448 INFO    MainThread:1199 [wandb_setup.py:_flush():71] setting login settings: {}
2022-02-03 15:44:51,449 INFO    MainThread:1199 [wandb_init.py:_log_setup():371] Logging user logs to /Users/liwenyu/Documents/GitHub/RTDM/wandb/run-20220203_154451-3i31rgxo/logs/debug.log
2022-02-03 15:44:51,449 INFO    MainThread:1199 [wandb_init.py:_log_setup():372] Logging internal logs to /Users/liwenyu/Documents/GitHub/RTDM/wandb/run-20220203_154451-3i31rgxo/logs/debug-internal.log
2022-02-03 15:44:51,449 INFO    MainThread:1199 [wandb_init.py:_jupyter_setup():321] configuring jupyter hooks <wandb.sdk.wandb_init._WandbInit object at 0x7feeb9e437c0>
2022-02-03 15:44:51,450 INFO    MainThread:1199 [wandb_init.py:init():404] calling init triggers
2022-02-03 15:44:51,450 INFO    MainThread:1199 [wandb_init.py:init():409] wandb.init called with sweep_config: {}
config: {}
2022-02-03 15:44:51,450 INFO    MainThread:1199 [wandb_init.py:init():449] starting backend
2022-02-03 15:44:51,450 INFO    MainThread:1199 [backend.py:_multiprocessing_setup():95] multiprocessing start_methods=spawn,fork,forkserver, using: spawn
2022-02-03 15:44:51,494 INFO    MainThread:1199 [backend.py:ensure_launched():199] starting backend process...
2022-02-03 15:44:51,503 INFO    MainThread:1199 [backend.py:ensure_launched():204] started backend process with pid: 1212
2022-02-03 15:44:51,504 INFO    MainThread:1199 [wandb_init.py:init():458] backend started and connected
2022-02-03 15:44:51,572 INFO    MainThread:1199 [wandb_run.py:_label_probe_notebook():917] probe notebook
2022-02-03 15:44:51,574 INFO    MainThread:1199 [wandb_run.py:_label_probe_notebook():927] Unable to probe notebook: 'NoneType' object has no attribute 'get'
2022-02-03 15:44:51,574 INFO    MainThread:1199 [wandb_init.py:init():519] updated telemetry
2022-02-03 15:44:51,595 INFO    MainThread:1199 [wandb_init.py:init():549] communicating current version
2022-02-03 15:44:56,601 INFO    MainThread:1199 [wandb_init.py:init():564] communicating run to backend with 30 second timeout
2022-02-03 15:45:20,198 ERROR   Thread-8  :1199 [retry.py:__call__():126] Retry attempt failed:
Traceback (most recent call last):
  File "/Library/Frameworks/Python.framework/Versions/3.9/lib/python3.9/site-packages/urllib3/connection.py", line 169, in _new_conn
    conn = connection.create_connection(
  File "/Library/Frameworks/Python.framework/Versions/3.9/lib/python3.9/site-packages/urllib3/util/connection.py", line 96, in create_connection
    raise err
  File "/Library/Frameworks/Python.framework/Versions/3.9/lib/python3.9/site-packages/urllib3/util/connection.py", line 86, in create_connection
    sock.connect(sa)
socket.timeout: timed out

During handling of the above exception, another exception occurred:

Traceback (most recent call last):
  File "/Library/Frameworks/Python.framework/Versions/3.9/lib/python3.9/site-packages/urllib3/connectionpool.py", line 699, in urlopen
    httplib_response = self._make_request(
  File "/Library/Frameworks/Python.framework/Versions/3.9/lib/python3.9/site-packages/urllib3/connectionpool.py", line 382, in _make_request
    self._validate_conn(conn)
  File "/Library/Frameworks/Python.framework/Versions/3.9/lib/python3.9/site-packages/urllib3/connectionpool.py", line 1010, in _validate_conn
    conn.connect()
  File "/Library/Frameworks/Python.framework/Versions/3.9/lib/python3.9/site-packages/urllib3/connection.py", line 353, in connect
    conn = self._new_conn()
  File "/Library/Frameworks/Python.framework/Versions/3.9/lib/python3.9/site-packages/urllib3/connection.py", line 174, in _new_conn
    raise ConnectTimeoutError(
urllib3.exceptions.ConnectTimeoutError: (<urllib3.connection.HTTPSConnection object at 0x7feebb6c2d00>, 'Connection to api.wandb.ai timed out. (connect timeout=10)')

During handling of the above exception, another exception occurred:

Traceback (most recent call last):
  File "/Library/Frameworks/Python.framework/Versions/3.9/lib/python3.9/site-packages/requests/adapters.py", line 439, in send
    resp = conn.urlopen(
  File "/Library/Frameworks/Python.framework/Versions/3.9/lib/python3.9/site-packages/urllib3/connectionpool.py", line 755, in urlopen
    retries = retries.increment(
  File "/Library/Frameworks/Python.framework/Versions/3.9/lib/python3.9/site-packages/urllib3/util/retry.py", line 574, in increment
    raise MaxRetryError(_pool, url, error or ResponseError(cause))
urllib3.exceptions.MaxRetryError: HTTPSConnectionPool(host='api.wandb.ai', port=443): Max retries exceeded with url: /graphql (Caused by ConnectTimeoutError(<urllib3.connection.HTTPSConnection object at 0x7feebb6c2d00>, 'Connection to api.wandb.ai timed out. (connect timeout=10)'))

During handling of the above exception, another exception occurred:

Traceback (most recent call last):
  File "/Library/Frameworks/Python.framework/Versions/3.9/lib/python3.9/site-packages/wandb/sdk/lib/retry.py", line 102, in __call__
    result = self._call_fn(*args, **kwargs)
  File "/Library/Frameworks/Python.framework/Versions/3.9/lib/python3.9/site-packages/wandb/sdk/internal/internal_api.py", line 141, in execute
    return self.client.execute(*args, **kwargs)
  File "/Library/Frameworks/Python.framework/Versions/3.9/lib/python3.9/site-packages/wandb/vendor/gql-0.2.0/gql/client.py", line 52, in execute
    result = self._get_result(document, *args, **kwargs)
  File "/Library/Frameworks/Python.framework/Versions/3.9/lib/python3.9/site-packages/wandb/vendor/gql-0.2.0/gql/client.py", line 60, in _get_result
    return self.transport.execute(document, *args, **kwargs)
  File "/Library/Frameworks/Python.framework/Versions/3.9/lib/python3.9/site-packages/wandb/vendor/gql-0.2.0/gql/transport/requests.py", line 38, in execute
    request = requests.post(self.url, **post_args)
  File "/Library/Frameworks/Python.framework/Versions/3.9/lib/python3.9/site-packages/requests/api.py", line 117, in post
    return request('post', url, data=data, json=json, **kwargs)
  File "/Library/Frameworks/Python.framework/Versions/3.9/lib/python3.9/site-packages/requests/api.py", line 61, in request
    return session.request(method=method, url=url, **kwargs)
  File "/Library/Frameworks/Python.framework/Versions/3.9/lib/python3.9/site-packages/requests/sessions.py", line 542, in request
    resp = self.send(prep, **send_kwargs)
  File "/Library/Frameworks/Python.framework/Versions/3.9/lib/python3.9/site-packages/requests/sessions.py", line 655, in send
    r = adapter.send(request, **kwargs)
  File "/Library/Frameworks/Python.framework/Versions/3.9/lib/python3.9/site-packages/requests/adapters.py", line 504, in send
    raise ConnectTimeout(e, request=request)
requests.exceptions.ConnectTimeout: HTTPSConnectionPool(host='api.wandb.ai', port=443): Max retries exceeded with url: /graphql (Caused by ConnectTimeoutError(<urllib3.connection.HTTPSConnection object at 0x7feebb6c2d00>, 'Connection to api.wandb.ai timed out. (connect timeout=10)'))
2022-02-03 15:45:26,608 INFO    MainThread:1199 [interface_queue.py:_communicate_run():336] couldn't get run from backend
2022-02-03 15:45:26,609 ERROR   MainThread:1199 [wandb_init.py:init():569] backend process timed out
2022-02-03 15:45:26,609 ERROR   MainThread:1199 [wandb_init.py:init():578] encountered error: Error communicating with wandb process
try: wandb.init(settings=wandb.Settings(start_method='fork'))
or:  wandb.init(settings=wandb.Settings(start_method='thread'))
For more info see: https://docs.wandb.ai/library/init#init-start-error
2022-02-03 15:47:23,234 WARNING MainThread:1199 [wandb_init.py:init():938] interrupted
Traceback (most recent call last):
  File "/Library/Frameworks/Python.framework/Versions/3.9/lib/python3.9/site-packages/wandb/sdk/wandb_init.py", line 917, in init
    run = wi.init()
  File "/Library/Frameworks/Python.framework/Versions/3.9/lib/python3.9/site-packages/wandb/sdk/wandb_init.py", line 582, in init
    backend.cleanup()
  File "/Library/Frameworks/Python.framework/Versions/3.9/lib/python3.9/site-packages/wandb/sdk/backend/backend.py", line 230, in cleanup
    self.wandb_process.join()
  File "/Library/Frameworks/Python.framework/Versions/3.9/lib/python3.9/multiprocessing/process.py", line 149, in join
    res = self._popen.wait(timeout)
  File "/Library/Frameworks/Python.framework/Versions/3.9/lib/python3.9/multiprocessing/popen_fork.py", line 43, in wait
    return self.poll(os.WNOHANG if timeout == 0.0 else 0)
  File "/Library/Frameworks/Python.framework/Versions/3.9/lib/python3.9/multiprocessing/popen_fork.py", line 27, in poll
    pid, sts = os.waitpid(self.pid, flag)
KeyboardInterrupt
2022-02-03 15:47:25,769 INFO    MainThread:1199 [wandb_settings.py:_apply_source_login():798] setting login settings: {}
2022-02-03 15:47:25,780 INFO    MainThread:1199 [wandb_setup.py:_flush():71] setting env: {}
2022-02-03 15:47:25,780 INFO    MainThread:1199 [wandb_setup.py:_flush():71] setting login settings: {}
2022-02-03 15:47:25,780 INFO    MainThread:1199 [wandb_init.py:_log_setup():371] Logging user logs to /Users/liwenyu/Documents/GitHub/RTDM/wandb/run-20220203_154725-1mnvur0s/logs/debug.log
2022-02-03 15:47:25,781 INFO    MainThread:1199 [wandb_init.py:_log_setup():372] Logging internal logs to /Users/liwenyu/Documents/GitHub/RTDM/wandb/run-20220203_154725-1mnvur0s/logs/debug-internal.log
2022-02-03 15:47:25,781 INFO    MainThread:1199 [wandb_init.py:init():404] calling init triggers
2022-02-03 15:47:25,781 INFO    MainThread:1199 [wandb_init.py:init():409] wandb.init called with sweep_config: {}
config: {}
2022-02-03 15:47:25,781 INFO    MainThread:1199 [wandb_init.py:init():449] starting backend
2022-02-03 15:47:25,781 INFO    MainThread:1199 [backend.py:_multiprocessing_setup():95] multiprocessing start_methods=spawn,fork,forkserver, using: spawn
2022-02-03 15:47:25,784 INFO    MainThread:1199 [backend.py:ensure_launched():199] starting backend process...
2022-02-03 15:47:25,788 INFO    MainThread:1199 [backend.py:ensure_launched():204] started backend process with pid: 1243
2022-02-03 15:47:25,791 INFO    MainThread:1199 [wandb_init.py:init():458] backend started and connected
2022-02-03 15:47:25,809 INFO    MainThread:1199 [wandb_run.py:_label_probe_notebook():917] probe notebook
2022-02-03 15:47:25,809 INFO    MainThread:1199 [wandb_run.py:_label_probe_notebook():927] Unable to probe notebook: 'NoneType' object has no attribute 'get'
2022-02-03 15:47:25,809 INFO    MainThread:1199 [wandb_init.py:init():519] updated telemetry
2022-02-03 15:47:25,831 INFO    MainThread:1199 [wandb_init.py:init():549] communicating current version
2022-02-03 15:47:30,833 INFO    MainThread:1199 [wandb_init.py:init():564] communicating run to backend with 30 second timeout
2022-02-03 15:48:00,838 INFO    MainThread:1199 [interface_queue.py:_communicate_run():336] couldn't get run from backend
2022-02-03 15:48:00,839 ERROR   MainThread:1199 [wandb_init.py:init():569] backend process timed out
2022-02-03 15:48:00,839 ERROR   MainThread:1199 [wandb_init.py:init():578] encountered error: Error communicating with wandb process
try: wandb.init(settings=wandb.Settings(start_method='fork'))
or:  wandb.init(settings=wandb.Settings(start_method='thread'))
For more info see: https://docs.wandb.ai/library/init#init-start-error
2022-02-03 15:48:12,839 INFO    MainThread:1199 [wandb_init.py:teardown():219] tearing down wandb.init
2022-02-03 15:48:33,196 INFO    MainThread:1199 [wandb_settings.py:_apply_source_login():798] setting login settings: {}
2022-02-03 15:48:33,207 INFO    MainThread:1199 [wandb_setup.py:_flush():71] setting env: {}
2022-02-03 15:48:33,207 INFO    MainThread:1199 [wandb_setup.py:_flush():71] setting login settings: {}
2022-02-03 15:48:33,208 INFO    MainThread:1199 [wandb_init.py:_log_setup():371] Logging user logs to /Users/liwenyu/Documents/GitHub/RTDM/wandb/run-20220203_154833-3lm35i1r/logs/debug.log
2022-02-03 15:48:33,208 INFO    MainThread:1199 [wandb_init.py:_log_setup():372] Logging internal logs to /Users/liwenyu/Documents/GitHub/RTDM/wandb/run-20220203_154833-3lm35i1r/logs/debug-internal.log
2022-02-03 15:48:33,208 INFO    MainThread:1199 [wandb_init.py:init():404] calling init triggers
2022-02-03 15:48:33,208 INFO    MainThread:1199 [wandb_init.py:init():409] wandb.init called with sweep_config: {}
config: {}
2022-02-03 15:48:33,208 INFO    MainThread:1199 [wandb_init.py:init():449] starting backend
2022-02-03 15:48:33,208 INFO    MainThread:1199 [backend.py:_multiprocessing_setup():95] multiprocessing start_methods=spawn,fork,forkserver, using: spawn
2022-02-03 15:48:33,213 INFO    MainThread:1199 [backend.py:ensure_launched():199] starting backend process...
2022-02-03 15:48:33,218 INFO    MainThread:1199 [backend.py:ensure_launched():204] started backend process with pid: 1324
2022-02-03 15:48:33,221 INFO    MainThread:1199 [wandb_init.py:init():458] backend started and connected
2022-02-03 15:48:33,243 INFO    MainThread:1199 [wandb_run.py:_label_probe_notebook():917] probe notebook
2022-02-03 15:48:33,244 INFO    MainThread:1199 [wandb_run.py:_label_probe_notebook():927] Unable to probe notebook: 'NoneType' object has no attribute 'get'
2022-02-03 15:48:33,245 INFO    MainThread:1199 [wandb_init.py:init():519] updated telemetry
2022-02-03 15:48:33,272 INFO    MainThread:1199 [wandb_init.py:init():549] communicating current version
2022-02-03 15:48:34,765 INFO    MainThread:1199 [wandb_init.py:init():554] got version response upgrade_message: "wandb version 0.12.10 is available!  To upgrade, please run:\n $ pip install wandb --upgrade"

2022-02-03 15:48:34,767 INFO    MainThread:1199 [wandb_init.py:init():564] communicating run to backend with 30 second timeout
2022-02-03 15:48:34,986 INFO    MainThread:1199 [wandb_init.py:init():592] starting run threads in backend
2022-02-03 15:48:40,002 INFO    MainThread:1199 [wandb_run.py:_console_start():1816] atexit reg
2022-02-03 15:48:40,003 INFO    MainThread:1199 [wandb_run.py:_redirect():1690] redirect: SettingsConsole.WRAP
2022-02-03 15:48:40,004 INFO    MainThread:1199 [wandb_run.py:_redirect():1727] Wrapping output streams.
2022-02-03 15:48:40,005 INFO    MainThread:1199 [wandb_run.py:_redirect():1751] Redirects installed.
2022-02-03 15:48:40,005 INFO    MainThread:1199 [wandb_init.py:init():619] run started, returning control to user process
2022-02-03 15:48:53,671 INFO    MainThread:1199 [wandb_config.py:__setitem__():144] config set gamma = 0.99 - <bound method Run._config_callback of <wandb.sdk.wandb_run.Run object at 0x7feebb6d4af0>>
2022-02-03 15:48:53,671 INFO    MainThread:1199 [wandb_run.py:_config_callback():962] config_cb gamma 0.99 None
2022-02-03 15:48:53,672 INFO    MainThread:1199 [wandb_config.py:__setitem__():144] config set nenvs = 8 - <bound method Run._config_callback of <wandb.sdk.wandb_run.Run object at 0x7feebb6d4af0>>
2022-02-03 15:48:53,672 INFO    MainThread:1199 [wandb_run.py:_config_callback():962] config_cb nenvs 8 None
2022-02-03 15:48:53,672 INFO    MainThread:1199 [wandb_config.py:__setitem__():144] config set seed = 1 - <bound method Run._config_callback of <wandb.sdk.wandb_run.Run object at 0x7feebb6d4af0>>
2022-02-03 15:48:53,672 INFO    MainThread:1199 [wandb_run.py:_config_callback():962] config_cb seed 1 None
